Workbook

Sheet Sheet1
A1: sample ID | B1: Lab ID | C1: Patient Name | D1: Gender | E1: Date of Birth | F1: Native place | G1: =VLOOKUP(A1,Sheet2!B1:F815,5,FALSE) -> CYP2C9*2 (rs1799853) | H1: =VLOOKUP(A1,Sheet2!B1:G815,6,FALSE) -> CYP2C9*3 (rs1057910)
A2: OD2025001 | B2: OD001 | C2: Rupesh Chowdhary | D2: Male | E2: 32079 | F2: Hyderabad | G2: =VLOOKUP(A2,Sheet2!B2:F816,5,FALSE) -> #N/A | H2: =VLOOKUP(A2,Sheet2!B2:G816,6,FALSE) -> #N/A
A3: OD2025002 | B3: OD004 | C3: Jaylaxmi | D3: Female | E3: 25522 | F3: Hyderabad | G3: =VLOOKUP(A3,Sheet2!B3:F817,5,FALSE) -> #N/A | H3: =VLOOKUP(A3,Sheet2!B3:G817,6,FALSE) -> #N/A
A4: OD2025003 | B4: OD008 | C4: M. Prasanna | D4: Female | E4: 31315 | F4: West Godavari | G4: =VLOOKUP(A4,Sheet2!B4:F818,5,FALSE) -> #N/A | H4: =VLOOKUP(A4,Sheet2!B4:G818,6,FALSE) -> #N/A
A5: OD2025004 | B5: OD010 | C5: Chandrani Ghosh | D5: Female | E5: 34465 | F5: Durgapur, West Bengal | G5: =VLOOKUP(A5,Sheet2!B5:F819,5,FALSE) -> #N/A | H5: =VLOOKUP(A5,Sheet2!B5:G819,6,FALSE) -> #N/A
A6: OD2025005 | B6: OD003 | C6: Sree Venkateshwarlu Varanasi | D6: Male | E6: 33555 | F6: Hyderabad | G6: =VLOOKUP(A6,Sheet2!B6:F820,5,FALSE) -> #N/A | H6: =VLOOKUP(A6,Sheet2!B6:G820,6,FALSE) -> #N/A
A7: OD2025011 | B7: OD007 | C7: Pulak Giri | D7: Male | E7: 26051 | F7: Contai (WB) | G7: =VLOOKUP(A7,Sheet2!B7:F821,5,FALSE) -> #N/A | H7: =VLOOKUP(A7,Sheet2!B7:G821,6,FALSE) -> #N/A
A8: OD2025012 | B8: OD005 | C8: Subhas Karmakar | D8: Male | E8: 27932 | F8: Kolkata | G8: =VLOOKUP(A8,Sheet2!B8:F822,5,FALSE) -> #N/A | H8: =VLOOKUP(A8,Sheet2!B8:G822,6,FALSE) -> #N/A
A9: OD2025013 | B9: OD006 | C9: Tapas Chakrborty | D9: Male | E9: 21940 | F9: Howrah, WB | G9: =VLOOKUP(A9,Sheet2!B9:F823,5,FALSE) -> #N/A | H9: =VLOOKUP(A9,Sheet2!B9:G823,6,FALSE) -> #N/A
A10: OD2025028 | B10: OD018 | C10: M.R. Shankar | D10: Male | E10: 22432 | F10: Chennai | G10: =VLOOKUP(A10,Sheet2!B10:F824,5,FALSE) -> #N/A | H10: =VLOOKUP(A10,Sheet2!B10:G824,6,FALSE) -> #N/A
A11: OD2025030 | B11: OD002 | C11: Qamaar Unissa | D11: Female | E11: 36880 | F11: Hyderabad | G11: =VLOOKUP(A11,Sheet2!B11:F825,5,FALSE) -> #N/A | H11: =VLOOKUP(A11,Sheet2!B11:G825,6,FALSE) -> #N/A
A12: OD2025033 | B12: OD011 | C12: Debarchan Guha | D12: Male | E12: 34634 | F12: Kolkata | G12: =VLOOKUP(A12,Sheet2!B12:F826,5,FALSE) -> #N/A | H12: =VLOOKUP(A12,Sheet2!B12:G826,6,FALSE) -> #N/A
A13: OD2025034 | B13: OD012 | C13: Govinda Ch. Dey | D13: Male | E13: 18503 | F13: Balnagar - Hoogly | G13: =VLOOKUP(A13,Sheet2!B13:F827,5,FALSE) -> #N/A | H13: =VLOOKUP(A13,Sheet2!B13:G827,6,FALSE) -> #N/A
... A1274: OD2026773 | B1274: 30MOD1209 | C1274: SK. Kudan Saheb | D1274: Male | E1274: 26880 | F1274: Mattam Pally | G1274: =VLOOKUP(A1274,Sheet2!B1274:F2088,5,FALSE) -> #N/A | H1274: =VLOOKUP(A1274,Sheet2!B1274:G2088,6,FALSE) -> #N/A

Sheet Sheet2
A1: Lab ID | B1: sample ID | C1: Name | D1: Date of Birth | E1: Gender | F1: CYP2C9*2 (rs1799853) | G1: CYP2C9*3 (rs1057910) | H1: =VLOOKUP(B1,Sheet1!A1:F1274,6,FALSE) -> Native place | I1: State / Country
A2: 30MOD027 | B2: OD2025044 | C2: Barun Kanti Datta | D2: 27763 | E2: Male | F2: CT | G2: AA | H2: =VLOOKUP(B2,Sheet1!A2:F1275,6,FALSE) -> Bangladesh | I2: Bangladesh
A3: 30MOD031 | B3: OD2025051 | C3: Krishna Roy | D3: 21983 | E3: Female | F3: CC | G3: AA | H3: =VLOOKUP(B3,Sheet1!A3:F1276,6,FALSE) -> Kolkata | I3: West Bengal
A4: 30MOD035 | B4: OD2025078 | C4: S.SAYIA | D4: 21824 | E4: Female | H4: =VLOOKUP(B4,Sheet1!A4:F1277,6,FALSE) -> CHENNAI | I4: Tamil Nadu
A5: 30MOD036 | B5: OD2025056 | C5: SONALI GHATAK | D5: 25143 | E5: Female | F5: CC | G5: AC | H5: =VLOOKUP(B5,Sheet1!A5:F1278,6,FALSE) -> Bardhaman (West Bengal) | I5: West Bengal
A6: 30MOD037 | B6: OD2025074 | C6: SURSINH CHAVDA | D6: 19778 | E6: Male | F6: CC | G6: AC | H6: =VLOOKUP(B6,Sheet1!A6:F1279,6,FALSE) -> Ahmedabad | I6: Gujarat
A7: 30MOD038 | B7: OD2025062 | C7: J Vinay Kumar | D7: 35653 | E7: Male | F7: CC | G7: AA | H7: =VLOOKUP(B7,Sheet1!A7:F1280,6,FALSE) -> Hyderabad | I7: Telangana
A8: 30MOD039 | B8: OD2025077 | C8: Jyosna Devi | D8: 31651 | E8: Female | F8: CC | G8: AA | H8: =VLOOKUP(B8,Sheet1!A8:F1281,6,FALSE) -> Hyderabad | I8: Telangana
A9: 30MOD040 | B9: OD2025113 | C9: Saritha S | D9: 29258 | E9: Female | F9: CC | G9: AA | H9: =VLOOKUP(B9,Sheet1!A9:F1282,6,FALSE) -> Mahbub Nagar | I9: Telangana
A10: 30MOD042 | B10: OD2025057 | C10: Rajni Bagla | D10: 24453 | E10: Female | F10: CC | G10: AC | H10: =VLOOKUP(B10,Sheet1!A10:F1283,6,FALSE) -> Ranchi | I10: Jharkhand
A11: 30MOD044 | B11: OD2025079 | C11: K A Dhananjayan | D11: 28067 | E11: Male | H11: =VLOOKUP(B11,Sheet1!A11:F1284,6,FALSE) -> Rakkalub | I11: Needs review
A12: 30MOD043 | B12: OD2025058 | C12: Abitabha Guha | D12: 17847 | E12: Male | F12: CC | G12: AA | H12: =VLOOKUP(B12,Sheet1!A12:F1285,6,FALSE) -> Bhagalpur | I12: Bihar
A13: 30MOD046 | B13: OD2025064 | C13: G Sai Kumar | D13: 35758 | E13: Male | F13: CC | G13: AA | H13: =VLOOKUP(B13,Sheet1!A13:F1286,6,FALSE) -> Hyderabad | I13: Telangana
A14: 30MOD047 | B14: OD2025120 | C14: Chidanand | D14: 21839 | E14: Male | F14: CC | G14: AA | H14: =VLOOKUP(B14,Sheet1!A14:F1287,6,FALSE) -> Hyderabad | I14: Telangana
A15: 30MOD048 | B15: OD2025121 | C15: Sai Karthik Pulagam | D15: 37119 | E15: Male | F15: CC | G15: CC | H15: =VLOOKUP(B15,Sheet1!A15:F1288,6,FALSE) -> Hyderabad | I15: Telangana
A16: 30MOD049 | B16: OD2025061 | C16: VISHNU VARDHAN REDDY | D16: 33666 | E16: Male | F16: CC | G16: AA | H16: =VLOOKUP(B16,Sheet1!A16:F1289,6,FALSE) -> NULL
A17: 30MOD050 | B17: OD2025114 | C17: RAMAVATH SUNITHA | D17: 32725 | E17: Female | F17: CC | G17: AA | H17: =VLOOKUP(B17,Sheet1!A17:F1290,6,FALSE) -> HYDERABAD | I17: Telangana
A18: 30MOD051 | B18: OD2025117 | C18: MEDABOINA MANJULA | D18: 32544 | E18: Female | F18: CC | G18: AA | H18: =VLOOKUP(B18,Sheet1!A18:F1291,6,FALSE) -> NULL
A19: 30MOD052 | B19: OD2025125 | C19: NASEEHAH ATAHAR | D19: 40162 | E19: Female | F19: CC | G19: AA | H19: =VLOOKUP(B19,Sheet1!A19:F1292,6,FALSE) -> GUNTUR | I19: Andhra Pradesh
A20: 30MOD053 | B20: OD2025137 | C20: VINAY KUMAR SONI | D20: 35166 | E20: Male | F20: CC | G20: AA | H20: =VLOOKUP(B20,Sheet1!A20:F1293,6,FALSE) -> CHHATTISGARH | I20: Chhattisgarh
A21: 30M0D058 | B21: OD2025080 | C21: Vijayan NS | D21: 22772 | E21: Male | H21: =VLOOKUP(B21,Sheet1!A21:F1294,6,FALSE) -> Chennai | I21: Tamil Nadu
A22: 30MOD059 | B22: OD2025081 | C22: D SUGUMAR | D22: 25179 | E22: Male | H22: =VLOOKUP(B22,Sheet1!A22:F1295,6,FALSE) -> Tamil Nadu | I22: Tamil Nadu
A23: 30MOD54 | B23: OD2025026 | C23: Arunima | D23: 36577 | E23: Female | F23: CC | G23: AA | H23: =VLOOKUP(B23,Sheet1!A23:F1296,6,FALSE) -> NULL
A24: 30MOD055 | B24: OD2025024 | C24: SUNEETH TIRUNGARI | D24: 39627 | E24: Male | F24: CC | G24: AA | H24: =VLOOKUP(B24,Sheet1!A24:F1297,6,FALSE) -> GERMANY | I24: Germany
A25: 30MOD056 | B25: OD2025059 | C25: Ayan kumar das | D25: 36169 | E25: Male | F25: CC | G25: AA | H25: =VLOOKUP(B25,Sheet1!A25:F1298,6,FALSE) -> DHANIKALI | I25: West Bengal
A26: 30MOD066 | B26: OD2025110 | C26: RISHAAN N NAIR | D26: 43636 | E26: Male | H26: =VLOOKUP(B26,Sheet1!A26:F1299,6,FALSE) -> Kerala | I26: Kerala
A27: 30MOD060 | B27: OD2025119 | C27: VIKRAM ADITYA | D27: 36512 | E27: Male | F27: CC | G27: AA | H27: =VLOOKUP(B27,Sheet1!A27:F1300,6,FALSE) -> Hyderabad | I27: Telangana
A28: 30MOD061 | B28: OD2025127 | C28: Sharan Reddy | D28: 37849 | E28: Male | F28: CC | G28: AA | H28: =VLOOKUP(B28,Sheet1!A28:F1301,6,FALSE) -> Hyderabad | I28: Telangana
A29: 30MOD62 | B29: OD2025046 | C29: K Divya | D29: 34995 | E29: Female | F29: CT | G29: AA | H29: =VLOOKUP(B29,Sheet1!A29:F1302,6,FALSE) -> Karimnagar | I29: Telangana
A30: 30MOD63 | B30: OD2025060 | C30: Hariom Kumar | D30: 34956 | E30: Male | F30: CC | G30: AA | H30: =VLOOKUP(B30,Sheet1!A30:F1303,6,FALSE) -> Ara, Bihar | I30: Bihar
A31: 30MOD064 | B31: OD2025067 | C31: E.V.Surya kumari | D31: 22457 | E31: Female | F31: CC | G31: AA | H31: =VLOOKUP(B31,Sheet1!A31:F1304,6,FALSE) -> Hyderabad | I31: Telangana
A32: 30MOD065 | B32: OD2025068 | C32: Shaik Shabeena | D32: 33045 | E32: Female | F32: CC | G32: AA | H32: =VLOOKUP(B32,Sheet1!A32:F1305,6,FALSE) -> Nellore | I32: Andhra Pradesh
A33: 30MOD067 | B33: OD2025123 | C33: Padma | D33: 22820 | E33: Female | F33: CC | G33: AA | H33: =VLOOKUP(B33,Sheet1!A33:F1306,6,FALSE) -> Mahaboobnagar | I33: Telangana
A34: 30MGOD068 | B34: OD2025100 | C34: Arka Bikash Kundu | D34: 37231 | E34: Male | F34: CC | G34: AA | H34: =VLOOKUP(B34,Sheet1!A34:F1307,6,FALSE) -> Kolkata | I34: West Bengal
A35: 30MOD069 | B35: OD2025116 | C35: Paddaptla Baswavaj | D35: 33613 | E35: Male | F35: CC | G35: AA | H35: =VLOOKUP(B35,Sheet1!A35:F1308,6,FALSE) -> #N/A
A36: 30MOD070 | B36: OD2025133 | C36: Y Mary | D36: 37864 | E36: Female | F36: CC | G36: AA | H36: =VLOOKUP(B36,Sheet1!A36:F1309,6,FALSE) -> #N/A
A37: 30MOD071 | B37: OD2025169 | C37: Divya Bhargavi B | D37: 34291 | E37: Female | F37: CC | G37: AA | H37: =VLOOKUP(B37,Sheet1!A37:F1310,6,FALSE) -> #N/A
A38: 30MOD072 | B38: OD2025174 | C38: Rajshree Khelge | D38: 21768 | E38: Female | F38: CC | G38: AA | H38: =VLOOKUP(B38,Sheet1!A38:F1311,6,FALSE) -> #N/A
A39: 30MOD073 | B39: OD2025175 | C39: S Venkatesh | D39: 34816 | E39: Male | F39: CC | G39: AA | H39: =VLOOKUP(B39,Sheet1!A39:F1312,6,FALSE) -> Mancherial | I39: Telangana
A40: 30MOD76 | B40: OD2025128 | C40: PL SelvaKumar | D40: 22871 | E40: Male | H40: =VLOOKUP(B40,Sheet1!A40:F1313,6,FALSE) -> Karipatti | I40: Tamil Nadu
...
